Workbook

Sheet Dam Lines
A1: Mare | B1: Dam | C1: 2nd Dam | D1: 3rd Dam | E1: 4th Dam | F1: 5th Dam | G1: 6th Dam | H1: 7th Dam | I1: 8th Dam | J1: Dam Line
A2: DJEZIKA | B2: CHERIFA | C2: MANAGHI | D2: MANDRAGORE | E2: MAGNESIE | J2: MAGNESIE
A3: Sand Witchh | B3: TORNADE DU LOUP | C3: NEVADOU | D3: NEVADA II | J3: NEVADA II
A4: Dixies Valentine | B4: DIXIE DARLENE | C4: BW ALI CATT | D4: EL TALQUAHJAMASNA | E4: DAHSHUR | J4: DAHSHUR
A5: Waahiba | B5: CANELLE DE CARRERE | C5: QUATY DE CARRERE | D5: SAMBA | E5: JAVA | F5: NEVADA II | J5: NEVADA II
A6: Rudina | B6: REFLEKSJA | C6: RUSNEGA | J6: RUSNEGA
A7: Shumoos | B7: SHEENA | C7: FANTASIA | D7: FLEUR D'AVRIL | E7: FEDORA | F7: FATMA | J7: FATMA
A8: RB FRYNCH BROAD | B8: FRYNCH | C8: FRYGA | D8: FILGA | E8: PHILIPPA | J8: PHILIPPA
A9: Gabra | B9: UNCHAINEDD MELODY | C9: BLU BINT HALEEMA | D9: ASALA HALEEMA | J9: ASALA HALEEMA
A10: Fleur Du Cayrou | B10: LAFANA | C10: FLEUR DU CASSOU | D10: FLEUR DU BEARN | E10: FLEUR D'AVRIL | F10: FEDORA | G10: FATMA | J10: FATMA
A11: Fazzaha | B11: VERMEILLE | C11: WARKA | D11: ELOA | J11: ELOA
A12: Fazah | B12: ALEEFA | C12: ETOILE DU LOUP | D12: KALINE DU LOUP | E12: NIVADA | F12: NEVADA II | J12: NEVADA II
A13: WADYA | B13: ETOILE DU LOUP | C13: KALINE DU LOUP | D13: NIVADA | E13: NEVADA II | J13: NEVADA II
A14: Rich Kinkga | B14: GINKGA | C14: GENETIQUE | D14: GORA | E14: MARIE URSULE | F14: SAINTE URSULE | G14: MADOU | J14: MADOU
A15: Nevada Du Loup | B15: NIVADA | C15: NEVADA II | J15: NEVADA II
A16: MIZZNA | B16: UNCHAINEDD MELODY | C16: BLU BINT HALEEMA | D16: ASALA HALEEMA | J16: ASALA HALEEMA
A17: MENISSOU | B17: MENINE | C17: MANDORE | D17: MANDARINE III | E17: MAGNESIE | J17: MAGNESIE
A18: HABAIB | B18: EL AFIA | C18: MAHARZIA | D18: HALAZOUNA | J18: HALAZOUNA
A19: EARLY MORNING | B19: SHOAGH | C19: WIKINGS STREAK | J19: WIKINGS STREAK
A20: Caviyar | B20: TIKING AWAY | C20: MOLLY-O-TIKIE | D20: MOLLY-O-KU | E20: MONAT | J20: MONAT
A21: NO FRYLLS | B21: FRYGA | C21: FILGA | D21: PHILIPPA | J21: PHILIPPA
A22: Karraway | B22: KHADDOUJ | C22: JAWAHIR | D22: PRIMEROSE | J22: PRIMEROSE
A23: JOWHARAT AL ASAYL | B23: FLORINE DE CARRERE | C23: QUATY DE CARRERE | D23: SAMBA | E23: JAVA | F23: NEVADA II | J23: NEVADA II
A24: HAIFA'A | B24: AMIDA | C24: NE RIEN FAIRE | D24: NEFTA | E24: QUITAINE | J24: QUITAINE
A25: Fraynce | B25: FRYGA | C25: FILGA | D25: PHILIPPA | J25: PHILIPPA
A26: Fanar | B26: EL AFIA | C26: MAHARZIA | D26: HALAZOUNA | J26: HALAZOUNA
A27: BENT AL ASAYL | B27: KAHEELA | C27: ORZELA | D27: FAGAI | E27: GAICHI | J27: GAICHI
A28: BASHARRA | B28: BRYANS TIME | C28: ARGAPOVA | D28: ARRAGONDA | J28: ARRAGONDA
A29: ARKADYA | B29: ALBANY | C29: ALTIERE | D29: ASTRALE | J29: ASTRALE
A30: AF WAED | B30: SARALOUVE | C30: SARAVA DU LOUP | D30: NIVADA | E30: NEVADA II | J30: NEVADA II
A31: AF INTIDAB | B31: FLEUR DU CAYROU | C31: LAFANA | D31: FLEUR DU CASSOU | E31: FLEUR DU BEARN | F31: FLEUR D'AVRIL | G31: FEDORA | H31: FATMA | J31: FATMA
A32: VOICI KOSSACK | B32: VESNA | C32: STIHIA | D32: SAPINA | J32: SAPINA
A33: VALDORA | B33: VALINA DES FABRIES | C33: QUOVALINA | D33: NANOU | E33: NEVADA II | J33: NEVADA II
A34: STOOR | B34: TANGA | C34: TAKADA | D34: JAFFA DU BERLAIS | E34: NEFTA | F34: QUITAINE | J34: QUITAINE
A35: Sirella | B35: AKALIBA | C35: QUITAINE | D35: QUINE | J35: QUINE
A36: SHAJARET EDDOR AL REEF | B36: MAHABA | C36: JOYZELL | D36: YFS ALMOND JOY | J36: YFS ALMOND JOY
A37: ROSALYN | B37: ROGHEDA | C37: KHANA | D37: CAIDA | J37: CAIDA
A38: RB Burn Baby Burn | B38: BURNING FIRESTAR | C38: SAND AND SABLE | D38: SANLOU FARBANIN | E38: FARBAHAN | J38: FARBAHAN
A39: PRADORE | B39: PRALINE DU CASSOU | C39: NERVA DU CASO | D39: NEVADOUR | E39: NEVADA II | J39: NEVADA II
A40: MEN ABU DHABI | B40: ANSHOUDAT FARAH | C40: KASTANETA | D40: KARTINKA | E40: KARTA | J40: KARTA
...

Sheet Race Results 
A1: PLACE | B1: Horse Name | C1: SIRE | D1: DAM | E1: TYPE OF RACE | F1: DISTANCE | G1: Study Mare? | H1: GENDER | I1: Family
A2: 1 | B2: ROCKY CS | C2: Rubis De Carrere | D2: Willow CS | E2: MAIDEN | F2: 1200m | G2: =IF(COUNTIF('Dam Lines'!A:I,D2)>0,"Yes","No") -> No | H2: Male | I2: {=IF(G2="Yes",XLOOKUP(D2,'Dam Lines'!A:A,'Dam Lines'!J:J),"")}
A3: 2 | B3: AL ANID | C3: Mahabb | D3: Morgane De Piboul | E3: MAIDEN | F3: 1200m | G3: =IF(COUNTIF('Dam Lines'!A:A,D3)>0,"Yes","No") -> No | H3: Male | I3: {=IF(G3="Yes",XLOOKUP(D3,'Dam Lines'!A:A,'Dam Lines'!J:J),"")}
A4: 3 | B4: DAWLAH | C4: Calin Du Loup | D4: Fraynce | E4: MAIDEN | F4: 1200m | G4: =IF(COUNTIF('Dam Lines'!A:A,D4)>0,"Yes","No") -> Yes | H4: Male | I4: {=IF(G4="Yes",XLOOKUP(D4,'Dam Lines'!A:A,'Dam Lines'!J:J),"")} -> PHILIPPA
A5: 4 | B5: FRENCH ATHBAH | C5: KAOLINO | D5: Rocket Run | E5: MAIDEN | F5: 1200m | G5: =IF(COUNTIF('Dam Lines'!A:A,D5)>0,"Yes","No") -> No | H5: Male | I5: {=IF(G5="Yes",XLOOKUP(D5,'Dam Lines'!A:A,'Dam Lines'!J:J),"")}
A6: 5 | B6: ES MAYDAN | C6: BIG EASY | D6: Al Siada | E6: MAIDEN | F6: 1200m | G6: =IF(COUNTIF('Dam Lines'!A:A,D6)>0,"Yes","No") -> Yes | H6: Male | I6: {=IF(G6="Yes",XLOOKUP(D6,'Dam Lines'!A:A,'Dam Lines'!J:J),"")} -> AL SHIMRIYA-50
A7: 6 | B7: THE SECRET | C7: MADJANI | D7: More Adoraable | E7: MAIDEN | F7: 1200m | G7: =IF(COUNTIF('Dam Lines'!A:A,D7)>0,"Yes","No") -> No | H7: Male | I7: {=IF(G7="Yes",XLOOKUP(D7,'Dam Lines'!A:A,'Dam Lines'!J:J),"")}
A8: 7 | B8: AS FAYZ | C8: NIZAM | D8: AS MYSALOON | E8: MAIDEN | F8: 1200m | G8: =IF(COUNTIF('Dam Lines'!A:A,D8)>0,"Yes","No") -> Yes | H8: Male | I8: {=IF(G8="Yes",XLOOKUP(D8,'Dam Lines'!A:A,'Dam Lines'!J:J),"")} -> BUHTA
A9: 8 | B9: PRISM | C9: TAHAR DE CANDELON | D9: Tornade Blanche | E9: MAIDEN | F9: 1200m | G9: =IF(COUNTIF('Dam Lines'!A:A,D9)>0,"Yes","No") -> No | H9: Female | I9: {=IF(G9="Yes",XLOOKUP(D9,'Dam Lines'!A:A,'Dam Lines'!J:J),"")}
A10: 9 | B10: MUSHAAREK | C10: MADJANI | D10: Ester Du Paon | E10: MAIDEN | F10: 1200m | G10: =IF(COUNTIF('Dam Lines'!A:A,D10)>0,"Yes","No") -> No | H10: Male | I10: {=IF(G10="Yes",XLOOKUP(D10,'Dam Lines'!A:A,'Dam Lines'!J:J),"")}
A11: 10 | B11: JAP MIZOON | C11: Odin | D11: Firuze1 | E11: MAIDEN | F11: 1200m | G11: =IF(COUNTIF('Dam Lines'!A:A,D11)>0,"Yes","No") -> No | H11: Female | I11: {=IF(G11="Yes",XLOOKUP(D11,'Dam Lines'!A:A,'Dam Lines'!J:J),"")}
A12: 11 | B12: NICHEM AL MELS | C12: Dormane | D12: Jelifa Al Mels | E12: MAIDEN | F12: 1200m | G12: =IF(COUNTIF('Dam Lines'!A:A,D12)>0,"Yes","No") -> No | H12: Male | I12: {=IF(G12="Yes",XLOOKUP(D12,'Dam Lines'!A:A,'Dam Lines'!J:J),"")}
A13: 12 | B13: ES INTKHAB | C13: BIG EASY | D13: SHAMMA ONE | E13: MAIDEN | F13: 1200m | G13: =IF(COUNTIF('Dam Lines'!A:A,D13)>0,"Yes","No") -> Yes | H13: Male | I13: {=IF(G13="Yes",XLOOKUP(D13,'Dam Lines'!A:A,'Dam Lines'!J:J),"")} -> PL TSASSOON
A14: 13 | B14: AF AL RAQIB | C14: Martin Al Maury | D14: Etoile Du Pigne | E14: MAIDEN | F14: 1200m | G14: =IF(COUNTIF('Dam Lines'!A:A,D14)>0,"Yes","No") -> Yes | H14: Male | I14: {=IF(G14="Yes",XLOOKUP(D14,'Dam Lines'!A:A,'Dam Lines'!J:J),"")} -> ALTHEA
... A16: 15 | B16: DJAKBAR DEL FALOT | C16: Akbar | D16: Djeba De Falgas | E16: MAIDEN | F16: 1200m | G16: =IF(COUNTIF('Dam Lines'!A:A,D16)>0,"Yes","No") -> Yes | H16: Female | I16: {=IF(G16="Yes",XLOOKUP(D16,'Dam Lines'!A:A,'Dam Lines'!J:J),"")} -> MAMMONA
A17: 1 | B17: LATIFA PRINCESS | C17: BIG EASY | D17: FF Naomi | E17: HANDICAP (+) | F17: 1200m | G17: Yes | H17: Female | I17: {=XLOOKUP(B17,'Dam Lines'!A:A,'Dam Lines'!J:J)} -> TEBERDA
A18: 2 | B18: BIN ARAR | C18: Tanguy Du Falgas | D18: AL GHUBRAH | E18: HANDICAP (+) | F18: 1200m | G18: =IF(COUNTIF('Dam Lines'!A:A,D18)>0,"Yes","No") -> No | H18: Male | I18: {=IF(G18="Yes",XLOOKUP(D18,'Dam Lines'!A:A,'Dam Lines'!J:J),"")}
A19: 3 | B19: ATAB | C19: NEM KE TOI AL MAURY | D19: MKADER | E19: HANDICAP (+) | F19: 1200m | G19: =IF(COUNTIF('Dam Lines'!A:A,D19)>0,"Yes","No") -> No | H19: Female | I19: {=IF(G19="Yes",XLOOKUP(D19,'Dam Lines'!A:A,'Dam Lines'!J:J),"")}
A20: 4 | B20: MH LAZZAZ | C20: GERBYA | D20: SHEEMAH | E20: HANDICAP (+) | F20: 1200m | G20: =IF(COUNTIF('Dam Lines'!A:A,D20)>0,"Yes","No") -> No | H20: Male | I20: {=IF(G20="Yes",XLOOKUP(D20,'Dam Lines'!A:A,'Dam Lines'!J:J),"")}
A21: 5 | B21: JAP SHARAAR | C21: EASTER MOON | D21: Wizna | E21: HANDICAP (+) | F21: 1200m | G21: =IF(COUNTIF('Dam Lines'!A:A,D21)>0,"Yes","No") -> No | H21: Male | I21: {=IF(G21="Yes",XLOOKUP(D21,'Dam Lines'!A:A,'Dam Lines'!J:J),"")}
A22: 6 | B22: QAYED | C22: Haziz De Carrere | D22: Sirella | E22: HANDICAP (+) | F22: 1200m | G22: =IF(COUNTIF('Dam Lines'!A:A,D22)>0,"Yes","No") -> Yes | H22: Male | I22: {=IF(G22="Yes",XLOOKUP(D22,'Dam Lines'!A:A,'Dam Lines'!J:J),"")} -> QUINE
A23: 7 | B23: SAIF W'RSAN | C23: Samsheik | D23: SWEET MEMORRIES | E23: HANDICAP (+) | F23: 1200m | G23: =IF(COUNTIF('Dam Lines'!A:A,D23)>0,"Yes","No") -> Yes | H23: Male | I23: {=IF(G23="Yes",XLOOKUP(D23,'Dam Lines'!A:A,'Dam Lines'!J:J),"")} -> SHOGA
A24: 8 | B24: RS MUJAHID | C24: Bibi De Carrere | D24: MESHURA | E24: HANDICAP (+) | F24: 1200m | G24: =IF(COUNTIF('Dam Lines'!A:A,D24)>0,"Yes","No") -> No | H24: Male | I24: {=IF(G24="Yes",XLOOKUP(D24,'Dam Lines'!A:A,'Dam Lines'!J:J),"")}
A25: 9 | B25: AR MZOON | C25: Dormane | D25: SHEELA GHANTOOT | E25: HANDICAP (+) | F25: 1200m | G25: =IF(COUNTIF('Dam Lines'!A:A,D25)>0,"Yes","No") -> No | H25: Female | I25: {=IF(G25="Yes",XLOOKUP(D25,'Dam Lines'!A:A,'Dam Lines'!J:J),"")}
A26: 10 | B26: AZ ALDAHMA | C26: DAHESS | D26: AIRELLE DE GEMME | E26: HANDICAP (+) | F26: 1200m | G26: Yes | H26: Female | I26: {=XLOOKUP(B26,'Dam Lines'!A:A,'Dam Lines'!J:J)} -> FATMA
A27: 11 | B27: JAP MERSAL | C27: EASTER MOON | D27: Muznah | E27: HANDICAP (+) | F27: 1200m | G27: =IF(COUNTIF('Dam Lines'!A:A,D27)>0,"Yes","No") -> No | H27: Male | I27: {=IF(G27="Yes",XLOOKUP(D27,'Dam Lines'!A:A,'Dam Lines'!J:J),"")}
A28: 12 | B28: BAREK W'RSAN | C28: Drug | D28: PRINCE TIKI | E28: HANDICAP (+) | F28: 1200m | G28: =IF(COUNTIF('Dam Lines'!A:A,D28)>0,"Yes","No") -> No | H28: Male | I28: {=IF(G28="Yes",XLOOKUP(D28,'Dam Lines'!A:A,'Dam Lines'!J:J),"")}
A29: 13 | B29: MEHAJJ W'RSAN | C29: ZT Naphl | D29: Medeia | E29: HANDICAP (+) | F29: 1200m | G29: =IF(COUNTIF('Dam Lines'!A:A,D29)>0,"Yes","No") -> No | H29: Male | I29: {=IF(G29="Yes",XLOOKUP(D29,'Dam Lines'!A:A,'Dam Lines'!J:J),"")}
A30: 14 | B30: MAYDAN DU CAUSSE | C30: MOKTAR DU CAUSSE | D30: BENIKA | E30: HANDICAP (+) | F30: 1200m | G30: =IF(COUNTIF('Dam Lines'!A:A,D30)>0,"Yes","No") -> Yes | H30: Male | I30: {=IF(G30="Yes",XLOOKUP(D30,'Dam Lines'!A:A,'Dam Lines'!J:J),"")} -> BINT DASSIE
A31: 15 | B31: HADDAJ W'RSAN | C31: Tron Ku Tu | D31: KENIA KOLADA | E31: HANDICAP (+) | F31: 1200m | G31: =IF(COUNTIF('Dam Lines'!A:A,D31)>0,"Yes","No") -> Yes | H31: Male | I31: {=IF(G31="Yes",XLOOKUP(D31,'Dam Lines'!A:A,'Dam Lines'!J:J),"")} -> KHEMA
A32: 16 | B32: BOTHAYNAT AL ROOH | C32: Haziz De Carrere | D32: Asil | E32: HANDICAP (+) | F32: 1200m | G32: =IF(COUNTIF('Dam Lines'!A:A,D32)>0,"Yes","No") -> No | H32: Female | I32: {=IF(G32="Yes",XLOOKUP(D32,'Dam Lines'!A:A,'Dam Lines'!J:J),"")}
A33: 1 | B33: ES MUZAHIM | C33: MAJD AL ARAB | D33: Ghaddaf Al Naif | E33: MAIDEN | F33: 1000m | G33: =IF(COUNTIF('Dam Lines'!A:A,D33)>0,"Yes","No") -> Yes | H33: Male | I33: {=IF(G33="Yes",XLOOKUP(D33,'Dam Lines'!A:A,'Dam Lines'!J:J),"")} -> NEVADA II
A34: 2 | B34: MEFTAH AL REEF | C34: Bibi De Carrere | D34: MAFFIA | E34: MAIDEN | F34: 1000m | G34: =IF(COUNTIF('Dam Lines'!A:A,D34)>0,"Yes","No") -> Yes | H34: Male | I34: {=IF(G34="Yes",XLOOKUP(D34,'Dam Lines'!A:A,'Dam Lines'!J:J),"")} -> MADOU
A35: 3 | B35: NAWARAT AL REEF | C35: Bibi De Carrere | D35: NOMARCHIE | E35: MAIDEN | F35: 1000m | G35: =IF(COUNTIF('Dam Lines'!A:A,D35)>0,"Yes","No") -> Yes | H35: Female | I35: {=IF(G35="Yes",XLOOKUP(D35,'Dam Lines'!A:A,'Dam Lines'!J:J),"")} -> QUINE
A36: 4 | B36: IRENA | C36: MADJANI | D36: DENYAI | E36: MAIDEN | F36: 1000m | G36: =IF(COUNTIF('Dam Lines'!A:A,D36)>0,"Yes","No") -> Yes | H36: Female | I36: {=IF(G36="Yes",XLOOKUP(D36,'Dam Lines'!A:A,'Dam Lines'!J:J),"")} -> DEBORAH IV
A37: 5 | B37: AS ENJAZ | C37: Munjiz | D37: AS MYSALOON | E37: MAIDEN | F37: 1000m | G37: =IF(COUNTIF('Dam Lines'!A:A,D37)>0,"Yes","No") -> Yes | H37: Male | I37: {=IF(G37="Yes",XLOOKUP(D37,'Dam Lines'!A:A,'Dam Lines'!J:J),"")} -> BUHTA
A38: 6 | B38: ES KRAM | C38: MALEEH | D38: Bia | E38: MAIDEN | F38: 1000m | G38: =IF(COUNTIF('Dam Lines'!A:A,D38)>0,"Yes","No") -> No | H38: Male | I38: {=IF(G38="Yes",XLOOKUP(D38,'Dam Lines'!A:A,'Dam Lines'!J:J),"")}
... A89: 8 | B89: EKTIBAR | C89: KEY LINE | D89: DJANITI | E89: HANDICAP (+) | F89: 1000m | G89: =IF(COUNTIF('Dam Lines'!A:A,D89)>0,"Yes","No") -> No | H89: Male | I89: {=IF(G89="Yes",XLOOKUP(D89,'Dam Lines'!A:A,'Dam Lines'!J:J),"")}
A90: 9 | B90: AZ ALDAHMA | C90: DAHESS | D90: AIRELLE DE GEMME | E90: HANDICAP (+) | F90: 1000m | G90: Yes | H90: Female | I90: {=XLOOKUP(B90,'Dam Lines'!A:A,'Dam Lines'!J:J)} -> FATMA
A91: 10 | B91: RAFEEF | C91: Danzinon | D91: Tornade Blanche | E91: HANDICAP (+) | F91: 1000m | G91: =IF(COUNTIF('Dam Lines'!A:A,D91)>0,"Yes","No") -> No | H91: Female | I91: {=IF(G91="Yes",XLOOKUP(D91,'Dam Lines'!A:A,'Dam Lines'!J:J),"")}
...
